File: Datos/AISI316_data_RT_F_extensometer.csv
Extensometer_1_mm,Force_1_N,Extensometer_2_mm,Force_2_N
0.0,6.618430062783518,3.3929875,16992.32953410994
0.00023502255175670284,29.866956989550527,3.39306171875,17016.05848607733
0.00045318249909663896,53.803433519848106,3.3931129882799995,17039.794789371525
0.0005290361279252004,78.0141405525235,3.393154492185,17062.8689077662
0.0005129981361629509,102.19529525142508,3.3931818359349997,17087.50998974463
0.000497747289118487,125.73685624357496,3.3932008789049997,17111.737135475025
0.0005570393279823029,149.1910043050943,3.393212109375,17136.54786345675
0.0007175024959496508,172.42738344705216,3.393223828125,17161.285078170382
0.0008877899805682948,195.60880293880953,3.393239453125,17187.76512282452
0.0010418931759318044,219.71830482078659,3.39325703125,17212.94963750017
0.0009785168709798718,242.96888898808686,3.393229760745,17236.758323089107
0.000916460911347887,267.238898608647,3.39317373046875,17262.00164837923
0.0008724495659308031,291.1636446833035,3.3931166015625,17285.433719840854
0.00083439130953322,315.75500341816957,3.3930583740262503,17309.243536403148
0.0008906680565539323,339.17472465075383,3.3929946533175,17333.63128034999
0.0009512371677831697,362.7980606713581,3.39293312988,17358.138907472498
0.0010165754369196515,387.3449608436277,3.392867211945,17381.798304578537
0.0010585445637082247,411.9736303894849,3.3928056885075004,17405.877858286065
0.0011103859536396319,435.899778871102,3.39273867192,17431.083295968787
0.0011925153894606464,459.6728331444799,3.3927350683094994,17455.368121340303
0.0012956140372273265,483.7724616290652,3.3928194920544996,17480.749425379774
0.0013978389342788643,508.0116635354272,3.3929104101894993,17504.573379109006
0.001479094619384737,532.3693405556228,3.3930273045544994,17529.404464611125
0.0014811450128853084,556.7380445660325,3.3931636817569992,17553.616342201225
0.0014531133617443955,580.8712516495365,3.393332529246999,17578.776540949737
0.0014183372525370297,604.4645999116251,3.393498129874499,17601.685537234538
0.0014617056602847151,628.2415616979457,3.393712436431999,17625.752650235157
0.0015798476165259738,651.694216874636,3.3939429786319995,17649.03090932046
0.0017023651908191803,675.0696831198277,3.394199497061999,17673.032425866477
0.0018108808411138855,698.6405250121462,3.3944551367419993,17696.300506191583
0.0018608311254908836,722.6115618262347,3.3946390479619994,17721.044506745344
0.001872330061430575,746.0846310719882,3.394766196399499,17745.53121086078
0.0018903714537517528,770.7245255283966,3.3949228614094995,17768.858667287037
0.0019090076406732116,794.9133878107143,3.395109042991999,17792.49374846594
0.0019244717115357642,818.163485659472,3.3952588964494996,17816.48112784501
0.001933789794845722,842.6171653529316,3.3953815039294994,17840.02912407555
0.0019425131241584852,867.5536575717655,3.3955871437244998,17863.32604422122
0.0019490556008415142,891.8812337361102,3.3960863867544995,17886.5618918057
0.001956589381556802,917.1582620322225,3.3970464698069995,17910.332124300556
0.0020105541792574417,941.2244137054912,3.3988610742804988,17934.018664767118
0.0020974493078053133,965.3117711291716,3.4007876660089997,17957.844314956386
0.0021734825730911423,989.0896376941762,3.411912294907999,17933.677676300504
0.0022625501632720347,1012.5300218099616,3.4231600977104994,17910.48310924349
0.0023581346934489276,1036.1123430818363,3.4401358001819995,17887.17883777101
0.0024645813093393944,1060.3032976648617,3.4788528128284995,17864.145999903805
0.002679646780301818,1084.6492521462294,3.513259069459499,17864.157875124038
0.0030446063202028773,1108.874701416591,3.6063142389059992,17864.369367141477
0.0029577126871502797,1132.474043837463,3.6476929451474986,17864.15674415068
0.002877363420163869,1156.6449236434316,3.761197009717999,17864.09962999624
0.002798099940560052,1179.99239829808,3.8161459683189984,17864.067397255614
0.002855150049159496,1203.0394864295624,3.852372812841999,17864.27662732634
0.002924251580458275,1226.3057006486329,3.983499125414499,17875.529246724822
0.0030002632460176108,1250.646565749902,4.0900613235425,17863.922632666134
0.003054996883525115,1273.6723350336374,4.304246975502999,17863.703789321888
0.00311480235610116,1296.9885382750117,4.349728901666499,17864.338830860885
0.0031777763313413044,1320.5950623766894,4.485699645820499,17864.75616002899
0.003240438596646341,1344.5609532620117,4.6020804562399995,17853.11731322967
0.003271459336890243,1368.4346698188774,4.714987470931499,17853.082818542338
0.00330832458277439,1391.912941542065,4.789081503773499,17841.215515125255
0.003340469415753699,1415.7868842936016,4.855868969444499,17841.14935318397
0.003225053082287086,1439.7122297841365,5.0153674092735,17818.060532135678
0.0031366874442822876,1463.8388319832454,5.103074285706,17806.533651698537
0.0030429116425629748,1487.7996334884688,5.170375488730499,17794.06975983654
0.003383233343679944,1512.09870912426,5.198146931062999,17794.274466013845
0.0037700119798313634,1535.403715729417,5.263060627254999,17781.613219301347
0.00414142212126451,1559.1952105233527,5.324061240412499,17770.068808777203
0.00427351915283773,1582.6258682682828,5.370117689711499,17757.9413814884
0.0041441834521183055,1606.5855953488185,,
0.004023733252018387,1630.1545711351005,,
0.003913156088749003,1654.5638035756972,,
0.003927308942361943,1678.5260753462821,,
0.00409270504859944,1703.1553386531511,,
0.004244212917371948,1727.435640131244,,
0.00437930744985494,1750.967011053463,,
0.0044882962,1774.4002700371102,,
0.004470578571428571,1798.0194044916996,,
0.004451465842857143,1822.23501429387,,
0.0044404446428571425,1846.1398891666745,,
0.0044271913,1870.0072157240825,,
0.004459959539647577,1893.3082073738283,,
0.004528349247697236,1916.6436937109104,,
0.004611869378253904,1940.5396338942073,,
0.004697810475570684,1964.5417159268989,,
0.004774584487935522,1987.6611863531198,,
0.004824326468412092,2011.0576321540523,,
0.004889415439727672,2034.573112900629,,
0.004955562151531836,2058.2133965569624,,
0.0049843788693612785,2081.4319967977754,,
0.004940592149600799,2105.332404325826,,
0.004887034903792416,2128.924734711895,,
0.0048522950085828345,2152.4248342208393,,
0.0048161077103792424,2177.255354236283,,
0.004905812001101321,2200.116001410145,,
0.005046550439427312,2224.9615068225457,,
0.005134179092511012,2248.875259836189,,
0.005227119177312774,2272.6152387937914,,
0.0053415695159936,2297.3726979304824,,
0.0054434397054178305,2320.5012161435457,,
0.005585633104008395,2344.1954472289267,,
0.005731010285585762,2367.591214445846,,
0.0058331592555044024,2391.072426699757,,
0.005893574359062249,2415.565916655323,,
0.005957791336819455,2438.984868826026,,
0.006001729633281625,2462.634369915205,,
0.005989519254121706,2487.902520070478,,
0.005885205996402879,2511.790656537624,,
0.005794226344349522,2534.9237551927768,,
0.005700893514088731,2559.4811451429164,,
0.005627953020983214,2583.464226823239,,
0.005687245046559311,2606.81871351269,,
0.005775832590268052,2630.148375336992,,
0.005871741703590717,2653.558675561527,,
0.005977168257651528,2678.141455863494,,
0.006149449651512878,2701.681422183212,,
0.006317213486443977,2725.6135535138787,,
0.006541953106575791,2750.502827595129,,
0.006768274487043137,2774.0751963014773,,
0.006732039531569453,2797.9714192281135,,
0.006652429898276208,2822.736738629624,,
0.006575269637803169,2847.5346300637666,,
0.006504845466125477,2871.800794374919,,
0.006648262959173484,2895.4901622748716,,
0.006769502585346373,2918.9447401062657,,
0.006909191837193051,2942.2668809577553,,
0.007035702399431023,2966.415480588625,,
0.007167964388413414,2990.4076666044584,,
0.007126629296796798,3015.0411145127414,,
0.007082799817892894,3038.5180290679023,,
0.007034337696946948,3061.555956315207,,
0.007025229989591651,3085.3979490694564,,
0.00719973456644369,3108.9821929960353,,
0.007332270146216053,3133.870449201266,,
0.00747805837919329,3157.450904367104,,
0.007630312279636854,3180.8892527308503,,
0.007727913481242495,3205.445850999641,,
0.00783485026102941,3228.901163963717,,
0.007958760898334333,3252.47568151944,,
0.008024816692979383,3275.53549310117,,
0.008087172632355885,3298.464507614359,,
0.008151492922337869,3322.4089665545985,,
0.008202065271967573,3345.593015559407,,
0.008291210377245506,3369.1891347062165,,
0.008458566648952094,3392.360573358114,,
0.008632848773952094,3415.5723877587943,,
0.00882675257410179,3440.5671816540935,,
0.00878949066025641,3464.236587874326,,
0.008744095582682292,3487.8650528590965,,
0.008694525981019632,3511.707893843363,,
0.008629824864933897,3535.488135452413,,
0.008573245606624999,3559.0947726514264,,
0.008616128016225,3582.262422542583,,
0.008647915191925,3605.7533611673507,,
0.008698294530575,3629.2631304984825,,
0.008842828981231227,3653.2405573120295,,
0.00929085002377377,3676.9552590151407,,
0.009603753531981979,3700.1881660688978,,
0.009895322820420417,3723.17378579852,,
0.009892974020521271,3747.665918586059,,
0.009836934679548633,3770.8058030813436,,
0.00976698781076493,3794.648587516943,,
0.009716480253050611,3818.4318262053844,,
0.00969331452715543,3841.7822979394246,,
0.009677975053510703,3866.48852398312,,
0.009654496136477295,3890.5778040615055,,
0.009770685330845519,3913.905034293094,,
0.010051403515728308,3937.1805790423455,,
0.010236006651172108,3960.666880676356,,
0.010355007277699856,3984.25248177096,,
0.0105410741607713,4008.003091878102,,
0.01071117612003592,4031.879070381679,,
0.010815251653362602,4055.7833797678054,,
0.010952901344092993,4078.7269272886106,,
0.010983566609243697,4102.313602807903,,
0.010966102392857143,4126.280455020577,,
0.01094724100577731,4149.958286992306,,
0.0108657874475105,4173.263180500127,,
0.010779300181838633,4197.901435045171,,
0.010705168558788244,4222.441012164965,,
0.010606325650494903,4246.4672404787925,,
0.010700349617670602,4270.25313695462,,
0.010876023942965779,4293.829011678368,,
0.011045957054382629,4317.593645855117,,
0.011152611072702299,4340.44767683485,,
0.011149819537712288,4363.787630516686,,
0.011146954526923077,4387.420393200207,,
0.011143960956993007,4410.876554394298,,
0.011175087734693877,4435.479522570657,,
0.011209685948979592,4458.572471671697,,
0.011264672357142857,4482.533895212266,,
0.011297280542975,4505.872774469413,,
0.011277975105950001,4529.387180791302,,
0.011264152872050001,4552.7718644693405,,
0.011250216353575001,4578.012249228741,,
0.011335894032732734,4601.901742863913,,
0.01152232922647648,4626.0619349716735,,
0.011691157223473475,4649.305869015644,,
0.011771695945945945,4672.331921042719,,
0.011767406981981981,4696.86855763179,,
0.011762183277027027,4720.589762431695,,
0.01175245061936937,4745.2946878560315,,
0.011775578962445065,4768.655621093608,,
0.011917305560727126,4792.210233518278,,
0.012044584178785457,4816.7850970067575,,
0.012182785215120926,4840.000473973507,,
0.012349302919948029,4863.574482591221,,
0.012493688340345789,4887.552927280787,,
0.012659040210042004,4911.235848632614,,
0.012860721794358867,4935.715314518575,,
0.013051275441088216,4959.12912076051,,
0.013212619853970793,4982.695042918733,,
0.013361624059999999,5007.0208095257085,,
0.013389081116000002,5030.955542095093,,
0.013411124060000001,5054.34780329461,,
0.013437421034000002,5079.478200895209,,
0.013381982360666402,5102.42389726539,,
0.013253270150840503,5126.406130715696,,
0.013108998836802081,5149.64469263623,,
0.013238052269592163,5173.707281743429,,
0.013377107619452218,5198.938505618652,,
0.013543975178428622,5222.614414935677,,
0.013796604856143856,5246.38526946588,,
0.013776901902847152,5270.341603626349,,
0.013755631654845156,5293.730076065126,,
0.01374508981277533,5317.116399654528,,
0.013917628188325992,5340.975639752446,,
0.014103524675110132,5364.6478168573985,,
0.014270497075991189,5388.342613429458,,
0.014357165019496099,5411.824900108057,,
0.014402727339532092,5436.362611121815,,
0.014445675412417517,5461.934653817656,,
0.014477792868926214,5485.725413478911,,
0.014596938700509892,5510.97445018448,,
0.014801742964157164,5534.232973784733,,
0.01508383058638272,5557.954178584639,,
0.015052182544026417,5581.558384190937,,
0.01493031039273564,5604.800169385534,,
0.014814688485091052,5629.227836691822,,
0.0147900153275,5652.848215217102,,
0.01485962052575,5676.18053482879,,
0.014929225724,5699.424299226757,,
0.015050125779032583,5723.165126414376,,
0.015213635201878873,5747.538167707602,,
0.015436345018239055,5771.643168315625,,
0.015619586943333997,5794.807764578723,,
0.015749944407288746,5818.686570515689,,
0.015853551059271123,5842.738415376012,,
0.015944908898678414,5866.034770035001,,
0.01594974758096761,5889.106626482966,,
0.015942922163134747,5912.681200587356,,
0.01593465986605358,5936.86763127696,,
0.016016240959348782,5960.299702738584,,
0.01606209495155813,5984.552860856149,,
0.016125585928136236,6008.379076532094,,
0.016208829026917698,6032.5083930672545,,
0.016418351933660195,6056.586250314751,,
0.0166965155618371,6081.166825218675,,
0.016943103559635776,6105.006612574882,,
0.01700563110639361,6129.243371578796,,
0.016908952779720283,6152.414753682026,,
0.016792511398601398,6175.54881366453,,
0.01690787858677148,6198.855347083716,,
0.017024542487732823,6223.2544007641145,,
0.01714792129681554,6246.289500578032,,
0.017401746255992806,6270.203932175688,,
0.017702332477027568,6294.474054893583,,
0.017903683021873746,6318.813166986152,,
0.018075149547318925,6342.494052585941,,
0.018256862857643056,6366.940607147261,,
0.01840355928621448,6390.495954704613,,
0.0183694361719844,6413.861298738275,,
0.018240968876775357,6439.010187753232,,
0.018104139947739552,6464.080474119996,,
0.0182233225040008,6487.263165956779,,
0.01846284123024605,6510.448685226949,,
0.01872343925260051,6533.516017781492,,
0.01899130079368253,6556.789187486698,,
0.018866893336665337,6579.801102346831,,
0.018764891357457018,6603.32761008362,,
0.018794308523999995,6626.539141740963,,
0.018936068415,6650.13124593236,,
0.019064057776499995,6673.941062494652,,
0.019176699369873974,6697.441557844272,,
0.019273259419383876,6722.127313270238,,
0.019379015728145627,6746.948785498838,,
0.01952443425805483,6770.0822799946645,,
0.019631856465379228,6793.9294186776815,,
0.019739277963027817,6817.341698105588,,
0.01990165556279976,6841.941499556552,,
0.02001276032623901,6866.088911665397,,
0.020191066713129494,6890.06158839085,,
0.020276491223228582,6913.18490412648,,
0.020230977476230986,6936.701233103074,,
0.02017646654848879,6960.64224257458,,
0.020155524278577138,6984.003628201497,,
0.020144167146282973,7007.672638581055,,
0.02013407804606315,7032.150860396326,,
0.020225167682609565,7055.610075218476,,
0.020298758712227336,7079.013872346218,,
0.020372349741845108,7103.082681806871,,
0.020401713436000002,7126.830860321301,,
0.020417354138,7149.820155714327,,
0.020448334626,7173.726670498495,,
0.02057744412834866,7197.471456092858,,
0.020830996133546578,7222.073519490532,,
0.02105496476359456,7245.55987767321,,
0.021388807083166733,7269.1751668183915,,
0.02152984821893136,7292.7978072903825,,
0.02150713933360016,7316.370119448064,,
0.021490347076673324,7340.25797317187,,
0.021528969259490507,7363.265929625259,,
0.021548746916833166,7386.345137400032,,
0.021568524383116884,7409.77155399488,,
0.021740699809771724,7432.9887405189975,,
0.02195332313976772,7456.3161969452585,,
0.022228176069283137,7480.822127607733,,
0.022159789517828606,7504.948616709506,,
0.022080374140531364,7529.360111096812,,
0.022117183688524587,7552.739592297415,,
0.022341631351459414,7576.095888544236,,
0.022665381908236706,7598.891222006829,,
0.02271627925629748,7622.251476660393,,
0.022682568340163935,7645.845277311824,,
0.02263798245001999,7669.112226663576,,
0.022680545676447023,7692.959930833268,,
0.023029557962397352,7716.752782795232,,
0.023425478363458836,7740.294558672318,,
0.023525060658604838,7763.779220394964,,
0.023464920912452527,7787.210726369911,,
0.02340706519588247,7811.783384460346,,
0.023451979189425768,7836.143985046667,,
0.023591835430672267,7859.985468862906,,
0.023795744047821307,7883.383045637193,,
0.023988458139116528,7906.512581726275,,
0.024175085877223664,7930.237009800243,,
0.02426423588394468,7953.112076884386,,
0.024178619535979155,7976.473462511304,,
0.02409972722289036,7999.43674551716,,
0.024057811828209225,8023.393023128961,,
0.024027349640896388,8047.991128119891,,
0.023988078901976444,8071.522725236781,,
0.02429047919996004,8095.118787834924,,
0.024742177729474627,8118.180465522689,,
0.02510353706701957,8141.23139896358,,
0.025294420080629005,8163.908545710546,,
0.025373869764372992,8187.263710984011,,
0.02549070679562299,8211.49707706786,,
0.025710237671397154,8235.202278594785,,
0.025851033011193278,8259.070340284876,,
0.02598566147111733,8283.570616080573,,
0.025962402080583886,8306.689973409459,,
0.02581841432413517,8279.678371278334,,
0.025765084463607285,8255.542834389718,,
0.02587778830901459,8255.986175944992,,
0.025623956197499995,8279.521731468627,,
0.02547309538553736,8304.237457688507,,
0.025409156487215347,8327.139668133175,,
0.02569618479946925,8350.769094445299,,
0.026133266537903065,8374.4901295992,,
0.026190579056938616,8398.072055030401,,
0.02621795147320536,8421.837198145158,,
0.02624638853929214,8445.320728894447,,
0.026337227945393688,8468.5825888661,,
0.026414407832983613,8492.105703682826,,
0.026522811939525805,8515.830697243471,,
0.026741272266906757,8539.848047416459,,
0.026857516750450176,8563.55946929684,,
0.02693367735394157,8587.127823047776,,
0.027038216531249996,8611.270145776523,,
0.027090408388249998,8635.330472937014,,
0.027140841080499998,8659.1606470197,,
0.027204674663528938,8683.410412217201,,
0.027249071124324054,8707.793066783948,,
0.027286546551999996,8730.944656853459,,
0.027411046263999997,8754.479081403737,,
0.027564046455999996,8778.17806257721,,
0.02768231407148562,8801.166226996884,,
0.027753765472244406,8824.826755076274,,
0.02779494635982428,8849.548136162932,,
0.027839999275159743,8872.817347461394,,
0.02799642411945444,8896.603979069903,,
0.028226671267985608,8920.202869101433,,
0.028294032211981564,8943.9702741629,,
0.028341242189941898,8968.01816061648,,
0.028507379570359287,8992.218728473026,,
0.02870243424126747,9016.037027335482,,
0.029022594386477044,9039.55957666553,,
0.029118677529505903,9062.638784440303,,
0.029212499314112825,9086.278389512625,,
0.029305203675735147,9110.60110249154,,
0.029392927832899478,9134.266154464354,,
0.02947014561799159,9157.870133875982,,
0.0295240393737505,9181.139345174444,,
0.029561423402638946,9204.308465330963,,
0.029598807250099956,9228.196884541447,,
0.029726078711999997,9251.418594958986,,
0.029834715328,9275.76618935172,,
0.0298825337602541,9299.560737773716,,
0.02989035888380352,9323.000726048827,,
0.029902023705982397,9347.087631083165,,
0.029996099471683017,9370.731194562228,,
0.030257371798579152,9394.785301369262,,
0.030503713950620376,9418.374012640596,,
0.03066544572313224,9441.771589414884,,
0.030753195980823014,9465.449647581285,,
0.030870892590890927,9489.718073839147,,
0.0310896245905,9513.31583289732,,
0.031230814436500002,9537.459852086102,,
0.03126714638927786,9560.921328854962,,
0.031212330796159236,9584.360186156719,,
0.03126432476881505,9607.826752305678,,
0.03146008127451961,9631.634306921258,,
0.03167632374999999,9654.9951270615,,
0.031772336197313227,9678.311839240887,,
0.03178466197088494,9702.338237200716,,
0.03196679763949999,9725.979538733067,,
0.032209029247999996,9749.365805773803,,
0.0324028137515,9773.266665691195,,
0.03251385601495299,9797.165829148556,,
0.032606580715143024,9821.012402344895,,
0.03276980025330066,9844.346644611285,,
0.03287793790433086,9867.964195703178,,
0.03301820246624324,9891.099386659038,,
0.03311475083149669,9914.416098838421,,
0.033215028778300945,9937.441019892138,,
0.033321846526497695,9961.637629341943,,
0.03346664229962022,9985.769773310492,,
0.033695225773535877,10008.935500546946,,
0.03374847893295727,10032.44447819673,,
0.033762482219948084,10056.119143443062,,
0.03380400906,10080.271644932007,,
0.03388065713499999,10103.375168633918,,
0.033958877375,10126.737119747515,,
0.03405513275125249,10150.220085010127,,
0.03421013300776552,10173.65950779856,,
0.03431555104766187,10197.008452718572,,
0.034304683304856115,10220.843150694678,,
0.03429487816996403,10244.410938958938,,
0.03460857859912071,10267.666578577138,,
0.03488222739008792,10293.185861365955,,
0.0350668412377451,10316.57665230011,,
0.03511254578431373,10339.905239699723,,
0.03521572126574685,10363.965566860214,,
0.03542655823335334,10388.221552411167,,
0.035613273305338936,10411.44043539532,,
0.03576904608421685,10435.453827161564,,
0.03590194274154831,10459.734694126333,,
0.03595322020908273,10484.337888497363,,
0.035991852342625905,10508.622148382201,,
0.03601991541142086,10532.146394172281,,
0.03619974012007204,10555.10176036465,,
0.03641948910596358,10579.240124686652,,
0.036714869593837525,10602.901218252724,,
0.03696870763305322,10627.651439159941,,
0.03710314033111756,10652.147756548897,,
0.0372585787177629,10675.949090811022,,
0.03724726043275965,10699.752121533184,,
0.037222249510206126,10724.655589330041,,
0.03717326954972984,10748.25730679496,,
0.03741160833200158,10771.668455249508,,
0.037843314610467436,10794.944452388103,,
0.037924037492003196,10819.012696362079,,
0.0379101319262295,10842.828167791151,,
0.03791801818439253,10866.167499437639,,
0.03856742562750601,10889.309476233628,,
0.03915328047289879,10912.806578663185,,
0.03904152676856658,10936.17079172349,,
0.03895220815831504,10935.007585627573,,
0.03877702323446893,10922.549348632348,,
0.03838507882089179,10945.654568794293,,
0.03855190137762237,10969.852309217451,,
0.03910874402158704,10993.077412555054,,
0.03971287534556912,11017.024076893338,,
0.039579661255501095,11040.608264271246,,
0.03956177602667866,11064.856898495394,,
0.03962107303532174,11089.386014111653,,
0.03975547974245604,11112.941361669002,,
0.0398855755890603,11136.18569155365,,
0.04005352760168303,11159.302786935821,,
0.04042269540975415,11182.865485819982,,
0.04062512304992004,11206.119994464827,,
0.040801600790775557,11229.871000412642,,
0.040937484318613715,11253.5451001723,,
0.04083219719193838,11277.040506141819,,
0.040996902525464333,11300.209626298338,,
0.041263204817255844,11323.196659744654,,
0.04106106167017017,11347.4882709563,,
0.040671900451951945,11371.211568056911,,
0.04081263531618971,11394.843256315748,,
0.04091314466680008,11418.094372040523,,
0.041141560560448355,11441.389595726157,,
0.04137020657225782,11465.27575298993,,
0.041732462065456,11488.41094394579,,
0.04219587167157255,11512.63413126944,,
0.042502172236105557,11535.871675313952,,
0.04255731864654138,11559.266424654856,,
0.042664038911540775,11582.918470434086,,
0.04287578744239631,11606.601052493905,,
0.04296367758035536,11629.928508920164,,
0.04292346772110202,11653.508172404654,,
0.04294834843718693,11677.507992490635,,
0.04325971027098777,11701.024321467226,,
0.04344139822652348,11724.575145131157,,
0.043444920585664334,11749.262597017156,,
0.0434487263553946,11772.554427782723,,
0.04362828450254847,11796.57686733581,,
0.04373324768813712,11820.779697139067,,
0.04385490974740156,11844.329955316318,,
0.04406458513122375,11868.049859496865,,
0.04426811095533747,11892.060989316396,,
0.04465308964900862,11915.63330147408,,
0.0449787480096845,11938.873672951979,,
0.04532807397577092,11962.547207224961,,
0.04511990984581498,11985.6778742874,,
0.04490494719162995,12010.38681466715,,
0.04545746123575286,12034.09314716743,,
0.045881886426176174,12057.308071744837,,
0.04591580777277277,12081.107144060254,,
0.045833026970067955,12104.828179214155,,
0.045603041858135115,12128.446861279403,,
0.04550811231935839,12151.648214176546,,
0.04563135853833866,12175.055969711033,,
0.046320716358326686,12198.991889802439,,
0.04684903454156663,12222.862778925917,,
0.047331498644789576,12246.968910507292,,
0.047320537995991986,12270.50390054425,,
0.04728694972211116,12293.91844191887,,
0.047212526088064775,12317.358430193979,,
0.04760724327553467,12340.78315032879,,
0.048191389747901235,12363.807505895833,,
0.04845601216906619,12387.625804758289,,
0.04859976466856629,12410.904629330273,,
0.04883727830146176,12435.924587382728,,
0.048633114727673205,12459.45788095965,,
0.04881727427393563,12483.341210790037,,
0.049211291769688185,12508.04902019643,,
0.049231260409,12531.458472190949,,
0.04924232732721545,12554.66547995487,,
0.04953668566238247,12578.156927517646,,
0.049800588100899094,12601.9803157602,,
0.050075739414585395,12625.31229607988,,
0.050176027327154316,12648.58490029841,,
0.05019994914153307,12671.4916346365,,
0.050296009341317366,12695.701815766564,,
0.05070332316167663,12719.123142981312,,
0.05129857242885772,12742.407622420073,,
0.05182593664000001,12766.409138966086,,
0.052005790616267464,12789.799364413564,,
0.051920094747504995,12813.924722541982,,
0.0519723510345,12837.393550637653,,
0.0520406300265,12861.03372119665,,
0.05230731904383766,12884.388320983437,,
0.05301195796568133,12908.080516316779,,
0.05388586126746505,12931.520504591892,,
0.05387523602300002,12954.68170793492,,
0.05335789210400002,12977.967318347037,,
0.05329714137849999,13001.036912848289,,
0.0536418456685,13024.42148342899,,
0.054085024999,13047.842810643737,,
0.0541902212685,13071.425301561616,,
0.05471660611848698,13095.327292452364,,
0.05472048840556113,13119.518812522068,,
0.054724708260270545,13143.56613348897,,
0.055217752126999996,13167.484523493371,,
0.05572101648825001,13178.634789803198,,
0.05561468936350002,13154.827235187615,,
0.05592641443862274,13166.980674863587,,
0.05583246160000001,13190.248755188693,,
0.056048877284569136,13213.553592147851,,
0.056516140580000006,13236.404908791528,,
0.057175069673153694,13260.036597050363,,
0.056896139985029945,13282.89583050753,,
0.05719776281999999,13306.429124084454,,
0.05756786378757515,13329.838010592295,,
0.05755981633266534,13353.608808573827,,
0.05764001719311378,13377.406184429212,,
0.05810876034431137,13401.231269131798,,
0.05837907153749999,13424.706317580923,,
0.05862485,13448.014547460145,,
0.05917641266,13471.34313485976,,
0.059317039205,13495.044943466619,,
0.05941758543999999,13519.32354848468,,
0.05975978785999999,13542.306058037577,,
0.059917745365,13566.107392299702,,
0.060114332024999995,13589.75943807893,,
0.060424695337499994,13613.862176740244,,
0.06072349355460922,13637.260319001209,,
0.06087878851953908,13661.381718722885,,
0.06102870393712575,13684.542922065915,,
0.06134038921843686,13707.980648394316,,
0.061951158429999986,13732.324849866985,,
0.06222549907499999,13756.317884112832,,
0.06260192658682635,13780.088682094365,,
0.06324783751999997,13803.089852707626,,
0.06385997771999999,13826.622015311192,,
0.06423689306863728,13851.065176952447,,
0.0643822104233467,13874.265398876236,,
0.0645417391516966,13898.83409855993,,
0.06469329509999999,13921.898603681084,,
0.0652542817525,13944.838701733155,,
0.06549416151,13967.92921924148,,
0.066084284335,13991.650254395383,,
0.06679200474999998,14014.838601098942,,
0.0678212921875,14038.270672560564,,
0.067510714825,14061.142346724642,,
0.06784228307499998,14084.830018164563,,
0.06854150905999998,14108.229856885557,,
0.06925524098,14131.75353718896,,
0.069725881785,14155.503977650102,,
0.0700641396875,14178.87667301057,,
0.07071360960079841,14202.1492772291,,
0.07073844241516966,14225.470513301903,,
0.07128650117,14248.747075927178,,
0.07199054735,14272.284893397522,,
0.0727375004725,14295.66550557148,,
0.07285165669749999,14319.14620888738,,
0.07308862570500001,14342.52625557466,,
0.07370301881250003,14365.665404937265,,
0.074485047585,14389.37569584429,,
0.07584094317750001,14413.050361090623,,
0.0757917916691617,14436.314483008988,,
0.0767818006513026,14460.011767722428,,
0.0771189101875,14483.680212615309,,
0.07845341546906191,14507.665895534348,,
0.07912553864000002,14530.41825200944,,
0.079157717,14554.140418136698,,
0.07979621128,14577.743266574971,,
0.08176706187749999,14601.446206155186,,
0.08205528754,14624.769138688025,,
0.0822865771375,14648.752559660354,,
0.08275357975000003,14673.089975292893,,
0.08410691562500001,14696.24495828247,,
0.08532005140718564,14719.675898770736,,
0.08591798635749999,14743.166215360157,,
0.086555855155,14766.597155848427,,
0.08759720130761522,14790.920434314023,,
0.08877712702404811,14814.129138537975,,
0.08995041207665333,14837.353110902226,,
0.09197152312500002,14860.694704495429,,
0.09269758145999998,14883.995583047834,,
0.09383832651946111,14907.612003166372,,
0.09554458823000006,14931.101188782439,,
0.09687912372,14954.357393887316,,
0.09767563575000003,14978.43129272807,,
0.09924697477000002,15001.380438566981,,
0.10000003485778446,15025.0404011597,,
0.10270206210000002,15048.142228401575,,
0.10440729547500002,15071.988801597916,,
0.10545293028000004,15095.006371324826,,
0.10705500265000001,15118.035250785288,,
0.1091864732164329,15141.873907168138,,
0.11156810956,15165.063384845052,,
0.11349317150000002,15188.175390847127,,
0.11539400106,15211.181650840485,,
0.11751608770500001,15222.511176427126,,
0.1197893633657685,15246.162091233,,
0.1217419795375,15269.962294521772,,
0.12417199102000002,15293.456569517935,,
0.12687076762500002,15316.63643392133,,
0.13104841726546906,15339.8270425716,,
0.1342587301,15363.7833201834,,
0.13685946960000003,15386.811068670508,,
0.14069154670000003,15410.396387021772,,
0.144210859375,15433.501607183718,,
0.148834610075,15456.543492837765,,
0.15321907430139722,15479.545228937704,,
0.15491409735,15491.504706683243,,
0.1586606116,15503.102272955084,,
0.1609650384231537,15526.180915243183,,
0.16483516886227545,15537.780177975059,,
0.169617293875,15561.026769806414,,
0.17582482755,15584.462799674782,,
0.17838536472500002,15608.222287922763,,
0.18498863055,15620.11786567373,,
0.19094307160000001,15644.327481317116,,
0.19691863045000002,15667.918454535158,,
0.20244674596693388,15679.615546462268,,
0.20621766849999995,15702.82538165958,,
0.21243762875000002,15714.529259426821,,
0.22054704195891786,15737.766237984659,,
0.22923526796407187,15761.048455476704,,
0.23572263990000003,15784.159895992105,,
0.24561685375751505,15807.47151879139,,
0.25180467754491015,15818.752412523752,,
0.2582228802894212,15842.162995491624,,
0.26975542927500007,15865.344556355052,,
0.2748674696250001,15876.572859826396,,
0.28448246169999997,15899.92067377305,,
0.2896795530561122,15911.288086967093,,
0.2974008069,15923.096014283023,,
0.306574529,15946.686987501063,,
0.31392010600000003,15958.170890950703,,
0.3209057185240964,15981.673082760355,,
0.326956193125,15981.848949117104,,
0.33479505460000003,16005.256139164912,,
0.33845496285,16016.666529346456,,
0.34999021457915835,16027.97626289938,,
0.35441068699999995,16028.338739859748,,
0.3626007057884232,16052.001529885854,,
0.3691988662500001,16064.159493455247,,
0.37314508066132274,16064.243750970214,,
0.3812093228000001,16087.525968462263,,
0.392439988125,16099.506934701554,,
0.4013498197604791,16122.620637163662,,
0.41052789610000007,16133.91001319619,,
0.42557529832499996,16157.473843053705,,
0.4310250884730539,16169.7556482055,,
0.44087157859281434,16181.587891448571,,
0.45465852914171667,16193.532101053812,,
0.4591605136,16206.403708810394,,
0.47228723449999993,16230.399005002955,,
0.4820529088176353,16242.683072101463,,
0.4981688049,16265.875377211763,,
0.5127064598196394,16277.233177132288,,
0.5243804028,16300.535752144733,,
0.5433327688627255,16323.949728032669,,
0.5530963968,16335.619676599254,,
0.5689372105788423,16347.585374698248,,
0.5689694371756487,16320.678387602486,,
0.5690352256986028,16295.823551659905,,
0.571172372,16307.564751547872,,
0.572889844,16331.504064559345,,
0.5755512634730539,16355.797937717702,,
0.5829162155750001,16379.179115378338,,
0.5895403475,16379.158757857942,,
0.600046195275,16390.60138078011,,
0.6093115766500001,16402.206863865442,,
0.6232136968499999,16425.76560434286,,
0.6345609372255491,16437.3026635402,,
0.6460422261000002,16460.582053598857,,
0.6594218731000001,16460.313447426975,,
0.667000304,16460.343418220888,,
0.6746454584331337,16484.419579008354,,
0.6867896139278558,16485.50135502269,,
0.7001034764000001,16508.83672826244,,
0.7160883052,16520.65370336521,,
0.7240968063500002,16531.559113943615,,
0.7334160788000003,16543.040755446542,,
0.74489540695,16554.533706683025,,
0.754693441733467,16566.005734912433,,
0.7728416595808384,16577.42913128756,,
0.7870098550000001,16600.67741957895,,
0.8109717893999999,16612.662909711664,,
0.8187184896000004,16623.952285744188,,
0.8292450250000002,16635.46276706768,,
0.8365913007750001,16635.674259085114,,
0.8537668077000002,16658.8467721617,,
0.8703813730000001,16670.872977335202,,
0.8891601183000001,16682.363101138297,,
0.9018591252505009,16694.439634626106,,
0.9052900760521044,16694.13144438679,,
0.9278293695109783,16717.449287539526,,
0.9411345817365269,16728.91848833555,,
0.9510319690119762,16740.728112111512,,
0.95495745595,16741.032343944084,,
0.9717477616766467,16752.815955332873,,
0.9886538156250003,16764.137564106026,,
1.0044302918000003,16775.393576424576,,
1.0139777718250003,16786.822062179806,,
1.0265506935,16798.02774618404,,
1.0393244246506987,16809.704480590754,,
1.0497157104,16809.9385920753,,
1.0668299435621242,16833.372925483636,,
1.0739837581836327,16833.42042636456,,
1.0853781986472946,16844.943913881634,,
1.103611051675,16856.77898455809,,
1.1096483451653307,16857.942756140685,,
1.119296286375,16857.9879950749,,
1.127021305,16869.46850560447,,
1.136252989425,16880.889640032885,,
1.147110454575,16880.480793164952,,
1.1630728240480963,16892.137170051272,,
1.1707799926,16903.304400961428,,
1.1801191142750003,16904.032747802237,,
1.1849623915918162,16914.95003360087,,
1.20565244365,16927.067847616152,,
1.2199294288577154,16938.758719189806,,
1.2295014824000001,16938.963425367117,,
1.2367996338,16950.218306712308,,
1.2416076841,16950.599444733045,,
1.2536699495,16962.47014107019,,
1.273123483782435,16974.39512412839,,
1.30437161375,16986.235849671626,,
1.31253876875,16997.38894341484,,
1.33864906875,17009.083207908563,,
1.3473214,17021.447008628616,,
1.3574835037500002,17021.441353761842,,
1.3669277225,17020.902444958047,,
1.3976376625000002,17043.914925304856,,
1.415201765,17055.504009276538,,
1.4194165074999998,17055.69175085351,,
1.435137125,17066.792819822385,,
1.4478334125,17067.08065254131,,
1.45344883625,17067.41937906122,,
1.4693452525,17079.028255066616,,
1.4810936474999998,17091.064073513637,,
1.48478193125,17090.602070898003,,
1.4960171974999998,17101.873351356844,,
1.5154697049999997,17113.647349472114,,
1.5332792499999996,17113.45621497507,,
1.5553010875,17125.430395374227,,
1.5656929062499998,17136.501493549185,,
1.5895715750000001,17148.231949190274,,
1.6092233999999996,17159.62141636475,,
1.6183011675,17159.660434945505,,
1.64208572125,17171.32020475189,,
1.654625475,17182.620325031294,,
1.6648513749999996,17182.67970113245,,
1.6694263062499999,17182.676308212383,,
1.6741599687500002,17183.40748248658,,
1.6858316199999996,17195.114753173886,,
1.7003073137499998,17194.89760628967,,
1.7158612075,17206.217518602793,,
1.7391085325,17217.514245962127,,
1.7518237925,17218.58527772959,,
1.7640846712499998,17230.021680298305,,
1.7910638187499999,17241.571180202554,,
1.81072218,17253.195889834926,,
1.8331594087499996,17253.17779426124,,
1.8402345425000002,17264.552558782092,,
1.8787192625,17277.130678952974,,
1.9034133812499996,17288.955570869235,,
1.94023355875,17301.164993726292,,
1.9575500437499997,17313.274890928085,,
1.97772031,17312.838335212942,,
1.9899323887499998,17324.37256697689,,
2.01945279625,17336.371628789868,,
2.02773145875,17336.63288363494,,
2.04310100625,17336.676991595796,,
2.0540412574999998,17348.319231315174,,
2.08660931125,17359.708133002965,,
2.09437663,17360.468147097723,,
2.1065353725,17361.01440722833,,
2.14196023,17372.830816844424,,
2.17405964,17384.602553012985,,
2.17959121625,17385.133545003293,,
2.1858491825,17385.52825470429,,
2.20459530625,17397.55219793108,,
2.2329222875,17409.193306677105,,
2.2526820712499998,17409.467002229085,,
2.2728636512500002,17421.169749022974,,
2.3056635712499998,17433.401791347136,,
2.3208323537499997,17433.147322342196,,
2.33761121375,17433.210091363417,,
2.3536822625,17444.160740876032,,
2.3646293637499998,17455.368121340303,,
2.3890551875,17455.324013379446,,
2.41201791875,17466.78755930869,,
2.4223183362499996,17466.570412424473,,
2.4598906062499997,17477.96044508562,,
2.4709830874999996,17477.344630093667,,
2.4860921749999996,17477.80719819598,,
2.4885813625,17477.5007044167,,
2.50816076375,17488.337125620426,,
2.5415085275,17499.55581581825,,
2.5651249987499996,17499.737902528454,,
2.58082813875,17511.051029001443,,
2.59548574875,17510.74170778877,,
2.61477803625,17510.795429023146,,
2.634236,17522.41504927542,,
2.65892602625,17523.218605844355,,
2.6787126399999996,17534.899864144492,,
2.68686530875,17534.6923305338,,
2.6921470225,17534.680455313566,,
2.7239238825000003,17546.149090622905,,
2.7447181125,17545.191721677653,,
2.7704990174999997,17557.630732125835,,
2.7767643124999997,17557.50236665001,,
2.7878696450000002,17558.077466601175,,
2.8103753675,17557.921957764822,,
2.8538248499999996,17569.293329365606,,
2.89360055875,17580.9808080192,,
2.92722191875,17581.165156676114,,
2.9394724375,17592.92727957115,,
2.9728980037499997,17592.7084362269,,
2.983991645,17592.6326610121,,
2.9973768924999997,17604.191774189865,,
3.00866256875,17604.29356179184,,
3.0121580725,17604.57460867063,,
3.0517201249999997,17616.67319613887,,
3.06188938625,17616.897694349896,,
3.0766412187500003,17616.60873065762,,
3.1294275587500002,17628.023079245908,,
3.1578865675,17628.473206641313,,
3.16711492,17628.19555268259,,
3.1898668499999996,17640.07529680658,,
3.2114255687499997,17640.078689726644,,
3.2409938675,17639.890948149667,,
3.2922509825,17651.692655112143,,
3.31465510875,17651.502651588453,,
3.363712345,17663.345639078398,,
3.3854750000000005,17663.43611694682,,